Workbook

Sheet Calculs mirroir
B2: voir la feuille "notes" pour les commentaires | F2: SENSIBILITE/BRUIT DE FOND PHEMTO | L2: version 1.0
B4: densité Pb | C4: 11.3 | D4: g/cm3 | E4: hauteur collimateur | F4: 202 | G4: cm | H4: densité Si | I4: 1 | J4: g/cm3 | K4: diamètre intégration | L4: 10 | M4: arcsec | N4: DE/E | O4: 0.5 | T4: erg/s/cm2
B5: densité Ta | C5: 16.65 | D5: g/cm3 | E5: rayon collimateur | F5: =15.2/2 -> 7.6 | G5: cm | H5: densité CdTe | I5: 6.2 | J5: g/cm3 | K5: % photons/tache | L5: 50 | M5: % | N5: S/N | O5: 3 | S5: 3-10 keV | T5: =SUM(P20:P28) -> 1.0310303e-14
B6: ép. collimateur | C6: 0.13 | D6: cm | E6: rayon jupe | F6: 190 | G6: cm | H6: épaisseur Si | I6: 0.045 | J6: cm | K6: distance focale | L6: 2000 | M6: cm | N6: Tobs (s) | O6: 1000000 | S6: 10-20 keV | T6: =SUM(P29:P40) -> 4.8640035e-14
B7: épaisseur jupe | C7: 0.01 | D7: cm | H7: épaisseur CdTe | I7: 0.2 | J7: cm | K7: rayon miroir | L7: 37.5 | M7: cm | N7: (voir note 3) | S7: 20-40 keV | T7: =SUM(P41:P65) -> 4.6299815e-13
B8: W mirroir | D8: =2*3.1415928*(1-$L$6/SQRT($L$6*$L$6+$L$7*$L$7)) -> 0.0011041751 | E8: stéradian | H8: taille pixels | I8: 0.013 | J8: cm | K8: (voir note 2) | S8: 40-80 keV | T8: =SUM(P66:P115) -> 5.8924958e-12
B9: W jupe | D9: =2*3.1415928*(1-$L$6/SQRT($L$6*$L$6+$F$6*$F$6)) -> 0.028162394 | E9: stéradian | L9: rayon focal | N9: =$L$6*TAN($L$4*PI()/180/3600/2) -> 0.048481368 | O9: cm | S9: 3-80 keV | T9: =SUM(P20:P115) -> 6.4144442e-12
B10: W collimateur | D10: =2*3.1415928-$D$11 -> 0.0044423581 | E10: stéradian | I10: poids collimateur | J10: =3.1415928*$C$6*(3+$F$5-$C$6)*$C$4*$F$4/1000 -> 9.7604477 | K10: kg | L10: tache focale | N10: =3.1415928*$L$6*TAN($L$4*PI()/180/3600/2)*$L$6*TAN($L$4*PI()/180/3600/2) -> 0.007384135 | O10: cm²
B11: W protégé collimateur | D11: =2*3.1415928*$F$4/SQRT($F$4*$F$4+$F$5*$F$5) -> 6.2787432 | E11: stéradian | F11: (voir note 1 pour le calcul des W) | I11: poids jupe | J11: =3.1415928*($F$6*$F$6-$L$7*$L$7)*$C$7*$C$5/1000 -> 18.14744 | K11: kg | L11: nb pixels/tache | N11: =INT($N$10/$I$8/$I$8) -> 43
B12: W non protégé | D12: =MAX(2*3.1415928-$D$11-$D$9,0) -> 0 | E12: stéradian | I12: poids total shield | J12: =SUM(J10:J11) -> 27.907888 | K12: kg
B14: Energie | C14: Surface mirroir | D14: Section efficace Ta | E14: Section efficace Pb | F14: fraction transmise collimateur | G14: fraction transmise jupe | H14: Section efficace Si | I14: Section efficace CdTe | J14: efficacité détecteur | K14: Fond diffus | L14: Bruit diffus | M14: Bruit interne | N14: Bruit total | O14: Sensibilité
B16: keV | C16: cm2 | D16: (cm2/g) | E16: (cm2/g) | H16: (cm2/g) | I16: (cm2/g) | K16: ph/s/cm2/keV/str | L16: Cts/s/keV | M16: Cts/s/keV | N16: Cts/s/keV | O16: ph/s/keV/cm2 | P16: erg/s/cm2
B17: 1.6060606 | C17: 666.7371 | D17: 1360 | E17: 2040 | F17: =EXP(-$C$5*$C$6*E17) -> 0 | G17: =EXP(-1*D17*$C$5*$C$7) -> 4.5536277e-99 | H17: 445 | I17: 2800 | J17: 1 | K17: =MIN(167*POWER(B17,-2.38),11.6*POWER(B17,-1.41)) -> 5.9474893 | L17: =K17*$N$10*J17*(G17*($D$10-$D$8)+MAX(G17*F17*($D$9-$D$10),0)+F17*$D$11+$D$12) -> 6.6757637e-103 | M17: =0.0000198*$K$120 -> 7.326e-06 | N17: =L17+M17 -> 7.326e-06 | O17: =100*$O$5*SQRT(N17)/(C17*J17*SQRT(($O$4*B17)*$O$6))/$L$5 -> 2.7180918e-08 | P17: =O17*B17*B17*0.0000000016021773 -> 1.1233072e-16
B18: 2.4090909 | C18: 601.33893 | D18: 2760 | E18: 856 | F18: =EXP(-$C$5*$C$6*E18) -> 0 | G18: =EXP(-1*D18*$C$5*$C$7) -> 2.6565243e-200 | H18: 1810 | I18: 1050 | J18: 1 | K18: =MIN(167*POWER(B18,-2.38),11.6*POWER(B18,-1.41)) -> 3.357724 | L18: =K18*$N$10*J18*(G18*($D$10-$D$8)+MAX(G18*F18*($D$9-$D$10),0)+F18*$D$11+$D$12) -> 2.198713e-204 | M18: =0.0000198*$K$120 -> 7.326e-06 | N18: =L18+M18 -> 7.326e-06 | O18: =100*$O$5*SQRT(N18)/(C18*J18*SQRT(($O$4*B18)*$O$6))/$L$5 -> 2.4606724e-08 | P18: =O18*B18*B18*0.0000000016021773 -> 2.2880776e-16
B19: 3.2121212 | C19: 614.65187 | D19: 1560 | E19: 1920 | F19: =EXP(-$C$5*$C$6*E19) -> 0 | G19: =EXP(-1*D19*$C$5*$C$7) -> 1.5716335e-113 | H19: 811 | I19: 518 | J19: 1 | K19: =MIN(167*POWER(B19,-2.38),11.6*POWER(B19,-1.41)) -> 2.2381097 | L19: =K19*$N$10*J19*(G19*($D$10-$D$8)+MAX(G19*F19*($D$9-$D$10),0)+F19*$D$11+$D$12) -> 8.6704655e-118 | M19: =0.0000198*$K$120 -> 7.326e-06 | N19: =L19+M19 -> 7.326e-06 | O19: =100*$O$5*SQRT(N19)/(C19*J19*SQRT(($O$4*B19)*$O$6))/$L$5 -> 2.0848486e-08 | P19: =O19*B19*B19*0.0000000016021773 -> 3.446426e-16
B20: 4.0151515 | C20: 626.21703 | D20: 914 | E20: 1236 | F20: =EXP(-$C$5*$C$6*E20) -> 0 | G20: =EXP(-1*D20*$C$5*$C$7) -> 8.1027315e-67 | H20: 448 | I20: 788.2 | J20: 0.99858076 | K20: =MIN(167*POWER(B20,-2.38),11.6*POWER(B20,-1.41)) -> 1.6339481 | L20: =K20*$N$10*J20*(G20*($D$10-$D$8)+MAX(G20*F20*($D$9-$D$10),0)+F20*$D$11+$D$12) -> 3.2588372e-71 | M20: =0.0000198*$K$120 -> 7.326e-06 | N20: =L20+M20 -> 7.326e-06 | O20: =100*$O$5*SQRT(N20)/(C20*J20*SQRT(($O$4*B20)*$O$6))/$L$5 -> 1.832908e-08 | P20: =O20*B20*B20*0.0000000016021773 -> 4.7342929e-16
B21: 4.8181818 | C21: 632.63736 | D21: 584 | E21: 797.9 | F21: =EXP(-$C$5*$C$6*E21) -> 0 | G21: =EXP(-1*D21*$C$5*$C$7) -> 5.9012193e-43 | H21: 272 | I21: 843.2 | J21: 0.99849102 | K21: =MIN(167*POWER(B21,-2.38),11.6*POWER(B21,-1.41)) -> 1.2635508 | L21: =K21*$N$10*J21*(G21*($D$10-$D$8)+MAX(G21*F21*($D$9-$D$10),0)+F21*$D$11+$D$12) -> 1.8352211e-47 | M21: =0.0000198*$K$120 -> 7.326e-06 | N21: =L21+M21 -> 7.326e-06 | O21: =100*$O$5*SQRT(N21)/(C21*J21*SQRT(($O$4*B21)*$O$6))/$L$5 -> 1.6563767e-08 | P21: =O21*B21*B21*0.0000000016021773 -> 6.1607851e-16
B22: 5.6212121 | C22: 637.3814 | D22: 398 | E22: 548.4 | F22: =EXP(-$C$5*$C$6*E22) -> 0 | G22: =EXP(-1*D22*$C$5*$C$7) -> 1.6619103e-29 | H22: 177 | I22: 619.6 | J22: 0.99840129 | K22: =MIN(167*POWER(B22,-2.38),11.6*POWER(B22,-1.41)) -> 1.0167115 | L22: =K22*$N$10*J22*(G22*($D$10-$D$8)+MAX(G22*F22*($D$9-$D$10),0)+F22*$D$11+$D$12) -> 4.1583419e-34 | M22: =0.0000198*$K$120 -> 7.326e-06 | N22: =L22+M22 -> 7.326e-06 | O22: =100*$O$5*SQRT(N22)/(C22*J22*SQRT(($O$4*B22)*$O$6))/$L$5 -> 1.5222297e-08 | P22: =O22*B22*B22*0.0000000016021773 -> 7.7063853e-16
B23: 6.4242424 | C23: 640.97599 | D23: 285 | E23: 394.8 | F23: =EXP(-$C$5*$C$6*E23) -> 0 | G23: =EXP(-1*D23*$C$5*$C$7) -> 2.4640022e-21 | H23: 121 | I23: 438.9 | J23: 0.99831156 | K23: =MIN(167*POWER(B23,-2.38),11.6*POWER(B23,-1.41)) -> 0.84222685 | L23: =K23*$N$10*J23*(G23*($D$10-$D$8)+MAX(G23*F23*($D$9-$D$10),0)+F23*$D$11+$D$12) -> 5.106767e-26 | M23: =0.0000198*$K$120 -> 7.326e-06 | N23: =L23+M23 -> 7.326e-06 | O23: =100*$O$5*SQRT(N23)/(C23*J23*SQRT(($O$4*B23)*$O$6))/$L$5 -> 1.4160575e-08 | P23: =O23*B23*B23*0.0000000016021773 -> 9.3634372e-16
B24: 7.2272727 | C24: 643.87141 | D24: 212 | E24: 293.9 | F24: =EXP(-$C$5*$C$6*E24) -> 5.3096226e-277 | G24: =EXP(-1*D24*$C$5*$C$7) -> 4.6802966e-16 | H24: 86.6 | I24: 321 | J24: 0.9982207 | K24: =MIN(167*POWER(B24,-2.38),11.6*POWER(B24,-1.41)) -> 0.71335223 | L24: =K24*$N$10*J24*(G24*($D$10-$D$8)+MAX(G24*F24*($D$9-$D$10),0)+F24*$D$11+$D$12) -> 8.2151168e-21 | M24: =0.0000198*$K$120 -> 7.326e-06 | N24: =L24+M24 -> 7.326e-06 | O24: =100*$O$5*SQRT(N24)/(C24*J24*SQRT(($O$4*B24)*$O$6))/$L$5 -> 1.3291891e-08 | P24: =O24*B24*B24*0.0000000016021773 -> 1.1123622e-15
B25: 8.030303 | C25: 646.35492 | D25: 162 | E25: 226.5 | F25: =EXP(-$C$5*$C$6*E25) -> 1.2109132e-213 | G25: =EXP(-1*D25*$C$5*$C$7) -> 1.9309674e-12 | H25: 64 | I25: 243.5 | J25: 0.99813097 | K25: =MIN(167*POWER(B25,-2.38),11.6*POWER(B25,-1.41)) -> 0.61487376 | L25: =K25*$N$10*J25*(G25*($D$10-$D$8)+MAX(G25*F25*($D$9-$D$10),0)+F25*$D$11+$D$12) -> 2.9211792e-17 | M25: =0.0000198*$K$120 -> 7.326e-06 | N25: =L25+M25 -> 7.326e-06 | O25: =100*$O$5*SQRT(N25)/(C25*J25*SQRT(($O$4*B25)*$O$6))/$L$5 -> 1.2562473e-08 | P25: =O25*B25*B25*0.0000000016021773 -> 1.297925e-15
B26: 8.8333333 | C26: 648.13859 | D26: 127 | E26: 178.4 | F26: =EXP(-$C$5*$C$6*E26) -> 1.9887288e-168 | G26: =EXP(-1*D26*$C$5*$C$7) -> 6.5558051e-10 | H26: 48.6 | I26: 188.9 | J26: 0.99804123 | K26: =MIN(167*POWER(B26,-2.38),11.6*POWER(B26,-1.41)) -> 0.53755422 | L26: =K26*$N$10*J26*(G26*($D$10-$D$8)+MAX(G26*F26*($D$9-$D$10),0)+F26*$D$11+$D$12) -> 8.6697498e-15 | M26: =0.0000198*$K$120 -> 7.326e-06 | N26: =L26+M26 -> 7.326e-06 | O26: =100*$O$5*SQRT(N26)/(C26*J26*SQRT(($O$4*B26)*$O$6))/$L$5 -> 1.1945959e-08 | P26: =O26*B26*B26*0.0000000016021773 -> 1.4934161e-15
B27: 9.6363636 | C27: 649.53345 | D27: 102 | E27: 143.2 | F27: =EXP(-$C$5*$C$6*E27) -> 2.4414388e-135 | G27: =EXP(-1*D27*$C$5*$C$7) -> 4.2109183e-08 | H27: 37.7 | I27: 149.4 | J27: 0.99795038 | K27: =MIN(167*POWER(B27,-2.38),11.6*POWER(B27,-1.41)) -> 0.47548892 | L27: =K27*$N$10*J27*(G27*($D$10-$D$8)+MAX(G27*F27*($D$9-$D$10),0)+F27*$D$11+$D$12) -> 4.9253368e-13 | M27: =0.0000198*$K$120 -> 7.326e-06 | N27: =L27+M27 -> 7.3260005e-06 | O27: =100*$O$5*SQRT(N27)/(C27*J27*SQRT(($O$4*B27)*$O$6))/$L$5 -> 1.1413863e-08 | P27: =O27*B27*B27*0.0000000016021773 -> 1.6981248e-15
B28: 10.439394 | C28: 650.69996 | D28: 212 | E28: 117.2 | F28: =EXP(-$C$5*$C$6*E28) -> 6.7365325e-111 | G28: =EXP(-1*D28*$C$5*$C$7) -> 4.6802966e-16 | H28: 29.9 | I28: 120.4 | J28: 0.99760345 | K28: =MIN(167*POWER(B28,-2.38),11.6*POWER(B28,-1.41)) -> 0.42474262 | L28: =K28*$N$10*J28*(G28*($D$10-$D$8)+MAX(G28*F28*($D$9-$D$10),0)+F28*$D$11+$D$12) -> 4.8884022e-21 | M28: =0.0000198*$K$120 -> 7.326e-06 | N28: =L28+M28 -> 7.326e-06 | O28: =100*$O$5*SQRT(N28)/(C28*J28*SQRT(($O$4*B28)*$O$6))/$L$5 -> 1.0950232e-08 | P28: =O28*B28*B28*0.0000000016021773 -> 1.911985e-15
... B39: 19.272727 | C39: 571.4712 | D39: 69.7 | E39: 94.84 | F39: =EXP(-$C$5*$C$6*E39) -> 7.0390863e-90 | G39: =EXP(-1*D39*$C$5*$C$7) -> 9.1199157e-06 | H39: 4.97 | I39: 22.41 | J39: 0.99145159 | K39: =MIN(167*POWER(B39,-2.38),11.6*POWER(B39,-1.41)) -> 0.14606687 | L39: =K39*$N$10*J39*(G39*($D$10-$D$8)+MAX(G39*F39*($D$9-$D$10),0)+F39*$D$11+$D$12) -> 3.2555459e-11 | M39: =0.0000198*$K$120 -> 7.326e-06 | N39: =L39+M39 -> 7.3260326e-06 | O39: =100*$O$5*SQRT(N39)/(C39*J39*SQRT(($O$4*B39)*$O$6))/$L$5 -> 9.2334333e-09 | P39: =O39*B39*B39*0.0000000016021773 -> 5.4949044e-15
B40: 20.075758 | C40: 573.33632 | D40: 62.7 | E40: 85.48 | F40: =EXP(-$C$5*$C$6*E40) -> 4.4279314e-81 | G40: =EXP(-1*D40*$C$5*$C$7) -> 2.9252369e-05 | H40: 4.41 | I40: 20 | J40: 0.99088726 | K40: =MIN(167*POWER(B40,-2.38),11.6*POWER(B40,-1.41)) -> 0.13254314 | L40: =K40*$N$10*J40*(G40*($D$10-$D$8)+MAX(G40*F40*($D$9-$D$10),0)+F40*$D$11+$D$12) -> 9.4700507e-11 | M40: =$K$120*0.0000066*(B40/10)^1.58 -> 7.3445862e-06 | N40: =L40+M40 -> 7.3446809e-06 | O40: =100*$O$5*SQRT(N40)/(C40*J40*SQRT(($O$4*B40)*$O$6))/$L$5 -> 9.0340614e-09 | P40: =O40*B40*B40*0.0000000016021773 -> 5.8336115e-15
B41: 20.878788 | C41: 574.62762 | D41: 56.6 | E41: 77.25 | F41: =EXP(-$C$5*$C$6*E41) -> 2.4135213e-73 | G41: =EXP(-1*D41*$C$5*$C$7) -> 8.07704e-05 | H41: 3.94 | I41: 17.93 | J41: 0.9903299 | K41: =MIN(167*POWER(B41,-2.38),11.6*POWER(B41,-1.41)) -> 0.12073075 | L41: =K41*$N$10*J41*(G41*($D$10-$D$8)+MAX(G41*F41*($D$9-$D$10),0)+F41*$D$11+$D$12) -> 2.380454e-10 | M41: =$K$120*0.0000066*(B41/10)^1.58 -> 7.8141187e-06 | N41: =L41+M41 -> 7.8143568e-06 | O41: =100*$O$5*SQRT(N41)/(C41*J41*SQRT(($O$4*B41)*$O$6))/$L$5 -> 9.1220792e-09 | P41: =O41*B41*B41*0.0000000016021773 -> 6.3711081e-15
B42: 21.681818 | C42: 575.81357 | D42: 51.2 | E42: 70.08 | F42: =EXP(-$C$5*$C$6*E42) -> 1.3263836e-66 | G42: =EXP(-1*D42*$C$5*$C$7) -> 0.00019848441 | H42: 3.54 | I42: 16.14 | J42: 0.98977254 | K42: =MIN(167*POWER(B42,-2.38),11.6*POWER(B42,-1.41)) -> 0.11035924 | L42: =K42*$N$10*J42*(G42*($D$10-$D$8)+MAX(G42*F42*($D$9-$D$10),0)+F42*$D$11+$D$12) -> 5.3441702e-10 | M42: =$K$120*0.0000066*(B42/10)^1.58 -> 8.2942451e-06 | N42: =L42+M42 -> 8.2947795e-06 | O42: =100*$O$5*SQRT(N42)/(C42*J42*SQRT(($O$4*B42)*$O$6))/$L$5 -> 9.2088103e-09 | P42: =O42*B42*B42*0.0000000016021773 -> 6.9359427e-15
B43: 22.484848 | C43: 576.8415 | D43: 46.5 | E43: 63.8 | F43: =EXP(-$C$5*$C$6*E43) -> 1.0618425e-60 | G43: =EXP(-1*D43*$C$5*$C$7) -> 0.00043409376 | H43: 3.19 | I43: 14.59 | J43: 0.98921518 | K43: =MIN(167*POWER(B43,-2.38),11.6*POWER(B43,-1.41)) -> 0.10120882 | L43: =K43*$N$10*J43*(G43*($D$10-$D$8)+MAX(G43*F43*($D$9-$D$10),0)+F43*$D$11+$D$12) -> 1.0712786e-09 | M43: =$K$120*0.0000066*(B43/10)^1.58 -> 8.7847985e-06 | N43: =L43+M43 -> 8.7858698e-06 | O43: =100*$O$5*SQRT(N43)/(C43*J43*SQRT(($O$4*B43)*$O$6))/$L$5 -> 9.2953634e-09 | P43: =O43*B43*B43*0.0000000016021773 -> 7.5293395e-15
B44: 23.287879 | C44: 577.47562 | D44: 42.4 | E44: 58.22 | F44: =EXP(-$C$5*$C$6*E44) -> 1.8682275e-55 | G44: =EXP(-1*D44*$C$5*$C$7) -> 0.00085912167 | H44: 2.89 | I44: 13.21 | J44: 0.98865086 | K44: =MIN(167*POWER(B44,-2.38),11.6*POWER(B44,-1.41)) -> 0.093099475 | L44: =K44*$N$10*J44*(G44*($D$10-$D$8)+MAX(G44*F44*($D$9-$D$10),0)+F44*$D$11+$D$12) -> 1.949192e-09 | M44: =$K$120*0.0000066*(B44/10)^1.58 -> 9.285621e-06 | N44: =L44+M44 -> 9.2875702e-06 | O44: =100*$O$5*SQRT(N44)/(C44*J44*SQRT(($O$4*B44)*$O$6))/$L$5 -> 9.385896e-09 | P44: =O44*B44*B44*0.0000000016021773 -> 8.1554171e-15
B45: 24.090909 | C45: 578.06236 | D45: 38.8 | E45: 53.35 | F45: =EXP(-$C$5*$C$6*E45) -> 7.0693232e-51 | G45: =EXP(-1*D45*$C$5*$C$7) -> 0.0015644828 | H45: 2.62 | I45: 12.03 | J45: 0.9880935 | K45: =MIN(167*POWER(B45,-2.38),11.6*POWER(B45,-1.41)) -> 0.085882738 | L45: =K45*$N$10*J45*(G45*($D$10-$D$8)+MAX(G45*F45*($D$9-$D$10),0)+F45*$D$11+$D$12) -> 3.2725364e-09 | M45: =$K$120*0.0000066*(B45/10)^1.58 -> 9.7965622e-06 | N45: =L45+M45 -> 9.7998347e-06 | O45: =100*$O$5*SQRT(N45)/(C45*J45*SQRT(($O$4*B45)*$O$6))/$L$5 -> 9.4749362e-09 | P45: =O45*B45*B45*0.0000000016021773 -> 8.8103517e-15
B46: 24.893939 | C46: 578.24954 | D46: 35.6 | E46: 49.03 | F46: =EXP(-$C$5*$C$6*E46) -> 8.1340941e-47 | G46: =EXP(-1*D46*$C$5*$C$7) -> 0.002665403 | H46: 2.39 | I46: 10.98 | J46: 0.98753614 | K46: =MIN(167*POWER(B46,-2.38),11.6*POWER(B46,-1.41)) -> 0.079435318 | L46: =K46*$N$10*J46*(G46*($D$10-$D$8)+MAX(G46*F46*($D$9-$D$10),0)+F46*$D$11+$D$12) -> 5.1539392e-09 | M46: =$K$120*0.0000066*(B46/10)^1.58 -> 1.0317479e-05 | N46: =L46+M46 -> 1.0322633e-05 | O46: =100*$O$5*SQRT(N46)/(C46*J46*SQRT(($O$4*B46)*$O$6))/$L$5 -> 9.5685556e-09 | P46: =O46*B46*B46*0.0000000016021773 -> 9.5004508e-15
B47: 25.69697 | C47: 578.23403 | D47: 32.8 | E47: 45.14 | F47: =EXP(-$C$5*$C$6*E47) -> 3.6900094e-43 | G47: =EXP(-1*D47*$C$5*$C$7) -> 0.0042484545 | H47: 2.19 | I47: 10.04 | J47: 0.98697181 | K47: =MIN(167*POWER(B47,-2.38),11.6*POWER(B47,-1.41)) -> 0.0736542 | L47: =K47*$N$10*J47*(G47*($D$10-$D$8)+MAX(G47*F47*($D$9-$D$10),0)+F47*$D$11+$D$12) -> 7.6127753e-09 | M47: =$K$120*0.0000066*(B47/10)^1.58 -> 1.0848235e-05 | N47: =L47+M47 -> 1.0855848e-05 | O47: =100*$O$5*SQRT(N47)/(C47*J47*SQRT(($O$4*B47)*$O$6))/$L$5 -> 9.6638186e-09 | P47: =O47*B47*B47*0.0000000016021773 -> 1.0224055e-14
B48: 26.5 | C48: 578.01139 | D48: 30.2 | E48: 41.71 | F48: =EXP(-$C$5*$C$6*E48) -> 6.1848869e-40 | G48: =EXP(-1*D48*$C$5*$C$7) -> 0.006549936 | H48: 2.01 | I48: 9.222 | J48: 0.98641445 | K48: =MIN(167*POWER(B48,-2.38),11.6*POWER(B48,-1.41)) -> 0.068452812 | L48: =K48*$N$10*J48*(G48*($D$10-$D$8)+MAX(G48*F48*($D$9-$D$10),0)+F48*$D$11+$D$12) -> 1.0901783e-08 | M48: =$K$120*0.0000066*(B48/10)^1.58 -> 1.13887e-05 | N48: =L48+M48 -> 1.1399601e-05 | O48: =100*$O$5*SQRT(N48)/(C48*J48*SQRT(($O$4*B48)*$O$6))/$L$5 -> 9.7609554e-09 | P48: =O48*B48*B48*0.0000000016021773 -> 1.0982334e-14
B49: 27.30303 | C49: 577.23529 | D49: 28 | E49: 38.64 | F49: =EXP(-$C$5*$C$6*E49) -> 4.7558167e-37 | G49: =EXP(-1*D49*$C$5*$C$7) -> 0.0094475484 | H49: 1.85 | I49: 27.03 | J49: 0.98585709 | K49: =MIN(167*POWER(B49,-2.38),11.6*POWER(B49,-1.41)) -> 0.063757994 | L49: =K49*$N$10*J49*(G49*($D$10-$D$8)+MAX(G49*F49*($D$9-$D$10),0)+F49*$D$11+$D$12) -> 1.4637857e-08 | M49: =$K$120*0.0000066*(B49/10)^1.58 -> 1.1938749e-05 | N49: =L49+M49 -> 1.1953386e-05 | O49: =100*$O$5*SQRT(N49)/(C49*J49*SQRT(($O$4*B49)*$O$6))/$L$5 -> 9.8659625e-09 | P49: =O49*B49*B49*0.0000000016021773 -> 1.178343e-14
B50: 28.106061 | C50: 576.49756 | D50: 25.9 | E50: 35.84 | F50: =EXP(-$C$5*$C$6*E50) -> 2.0384978e-34 | G50: =EXP(-1*D50*$C$5*$C$7) -> 0.013402018 | H50: 1.71 | I50: 25.05 | J50: 0.98529276 | K50: =MIN(167*POWER(B50,-2.38),11.6*POWER(B50,-1.41)) -> 0.059507612 | L50: =K50*$N$10*J50*(G50*($D$10-$D$8)+MAX(G50*F50*($D$9-$D$10),0)+F50*$D$11+$D$12) -> 1.9369472e-08 | M50: =$K$120*0.0000066*(B50/10)^1.58 -> 1.2498262e-05 | N50: =L50+M50 -> 1.2517631e-05 | O50: =100*$O$5*SQRT(N50)/(C50*J50*SQRT(($O$4*B50)*$O$6))/$L$5 -> 9.969298e-09 | P50: =O50*B50*B50*0.0000000016021773 -> 1.2617552e-14
B51: 28.909091 | C51: 574.71681 | D51: 24.1 | E51: 33.34 | F51: =EXP(-$C$5*$C$6*E51) -> 4.564427e-32 | G51: =EXP(-1*D51*$C$5*$C$7) -> 0.018085405 | H51: 1.59 | I51: 23.28 | J51: 0.9847354 | K51: =MIN(167*POWER(B51,-2.38),11.6*POWER(B51,-1.41)) -> 0.055648635 | L51: =K51*$N$10*J51*(G51*($D$10-$D$8)+MAX(G51*F51*($D$9-$D$10),0)+F51*$D$11+$D$12) -> 2.442936e-08 | M51: =$K$120*0.0000066*(B51/10)^1.58 -> 1.3067126e-05 | N51: =L51+M51 -> 1.3091555e-05 | O51: =100*$O$5*SQRT(N51)/(C51*J51*SQRT(($O$4*B51)*$O$6))/$L$5 -> 1.0089536e-08 | P51: =O51*B51*B51*0.0000000016021773 -> 1.3509854e-14
... B58: 34.530303 | C58: 514.07477 | D58: 15.1 | E58: 21.02 | F58: =EXP(-$C$5*$C$6*E58) -> 1.7400465e-20 | G58: =EXP(-1*D58*$C$5*$C$7) -> 0.080931675 | H58: 0.998 | I58: 27.74 | J58: 0.98723805 | K58: =MIN(167*POWER(B58,-2.38),11.6*POWER(B58,-1.41)) -> 0.036458563 | L58: =K58*$N$10*J58*(G58*($D$10-$D$8)+MAX(G58*F58*($D$9-$D$10),0)+F58*$D$11+$D$12) -> 7.180418e-08 | M58: =$K$120*0.0000066*(B58/10)^1.58 -> 1.7302238e-05 | N58: =L58+M58 -> 1.7374042e-05 | O58: =100*$O$5*SQRT(N58)/(C58*J58*SQRT(($O$4*B58)*$O$6))/$L$5 -> 1.1859553e-08 | P58: =O58*B58*B58*0.0000000016021773 -> 2.2655814e-14
B59: 35.333333 | C59: 486.8307 | D59: 14.2 | E59: 19.81 | F59: =EXP(-$C$5*$C$6*E59) -> 2.3877984e-19 | G59: =EXP(-1*D59*$C$5*$C$7) -> 0.094015088 | H59: 0.943 | I59: 26.13 | J59: 0.98781413 | K59: =MIN(167*POWER(B59,-2.38),11.6*POWER(B59,-1.41)) -> 0.034517322 | L59: =K59*$N$10*J59*(G59*($D$10-$D$8)+MAX(G59*F59*($D$9-$D$10),0)+F59*$D$11+$D$12) -> 7.901684e-08 | M59: =$K$120*0.000084*(B59/10)^(-0.45) -> 1.7611564e-05 | N59: =L59+M59 -> 1.7690581e-05 | O59: =100*$O$5*SQRT(N59)/(C59*J59*SQRT(($O$4*B59)*$O$6))/$L$5 -> 1.2485094e-08 | P59: =O59*B59*B59*0.0000000016021773 -> 2.4973051e-14
B60: 36.136364 | C60: 459.33923 | D60: 13.4 | E60: 18.67 | F60: =EXP(-$C$5*$C$6*E60) -> 2.8159978e-18 | G60: =EXP(-1*D60*$C$5*$C$7) -> 0.10741021 | H60: 0.892 | I60: 24.63 | J60: 0.98839741 | K60: =MIN(167*POWER(B60,-2.38),11.6*POWER(B60,-1.41)) -> 0.032719653 | L60: =K60*$N$10*J60*(G60*($D$10-$D$8)+MAX(G60*F60*($D$9-$D$10),0)+F60*$D$11+$D$12) -> 8.5624025e-08 | M60: =$K$120*0.000084*(B60/10)^(-0.45) -> 1.743436e-05 | N60: =L60+M60 -> 1.7519984e-05 | O60: =100*$O$5*SQRT(N60)/(C60*J60*SQRT(($O$4*B60)*$O$6))/$L$5 -> 1.3013548e-08 | P60: =O60*B60*B60*0.0000000016021773 -> 2.7226712e-14
...

Sheet Calculs lentille
B2: voir la feuille "notes" pour les commentaires | F2: SENSIBILITE/BRUIT DE FOND PHEMTO | L2: version 1.0
B4: densité Pb | C4: 11.3 | D4: g/cm3 | E4: hauteur collimateur | F4: 202 | G4: cm | H4: densité Si | I4: 1 | J4: g/cm3 | K4: diamètre intégration | L4: 10 | M4: arcsec | N4: DE/E | O4: 0.5
B5: densité Ta | C5: 16.65 | D5: g/cm3 | E5: rayon collimateur | F5: =15.2/2 -> 7.6 | G5: cm | H5: densité CdTe | I5: 6.2 | J5: g/cm3 | K5: % photons/tache | L5: 50 | M5: % | N5: S/N | O5: 3
B6: ép. collimateur | C6: 0.13 | D6: cm | E6: rayon jupe | F6: 190 | G6: cm | H6: épaisseur Si | I6: 0.045 | J6: cm | K6: distance focale | L6: 2000 | M6: cm | N6: Tobs (s) | O6: 1000000
B7: épaisseur jupe | C7: 0.01 | D7: cm | H7: épaisseur CdTe | I7: 0.2 | J7: cm | K7: rayon miroir | L7: 150 | M7: cm | N7: (voir note 3)
B8: W mirroir | D8: =2*3.1415928*(1-$L$6/SQRT($L$6*$L$6+$L$7*$L$7)) -> 0.017597256 | E8: stéradian | H8: taille pixels | I8: 0.025 | J8: cm | K8: (voir note 2)
B9: W jupe | D9: =2*3.1415928*(1-$L$6/SQRT($L$6*$L$6+$F$6*$F$6)) -> 0.028162394 | E9: stéradian | L9: rayon focal | N9: =$L$6*TAN($L$4*PI()/180/3600/2) -> 0.048481368 | O9: cm
B10: W collimateur | D10: =2*3.1415928-$D$11 -> 0.0044423581 | E10: stéradian | I10: poids collimateur | J10: =3.1415928*$C$6*(3+$F$5-$C$6)*$C$4*$F$4/1000 -> 9.7604477 | K10: kg | L10: tache focale | N10: =3.1415928*$L$6*TAN($L$4*PI()/180/3600/2)*$L$6*TAN($L$4*PI()/180/3600/2) -> 0.007384135 | O10: cm²
B11: W protégé collimateur | D11: =2*3.1415928*$F$4/SQRT($F$4*$F$4+$F$5*$F$5) -> 6.2787432 | E11: stéradian | F11: (voir note 1 pour le calcul des W) | I11: poids jupe | J11: =3.1415928*($F$6*$F$6-$L$7*$L$7)*$C$7*$C$5/1000 -> 7.1138227 | K11: kg | L11: nb pixels/tache | N11: =INT($N$10/$I$8/$I$8) -> 11
B12: W non protégé | D12: =MAX(2*3.1415928-$D$11-$D$9,0) -> 0 | E12: stéradian | I12: poids total shield | J12: =SUM(J10:J11) -> 16.87427 | K12: kg
B13: Energie | C13: Surface | D13: Section | E13: Section | F13: fraction | G13: fraction | H13: Section | I13: Section | J13: efficacité | K13: Fond diffus | L13: Bruit diffus | M13: Bruit interne | N13: Bruit total | O13: Sensibilité
C14: mirroir | D14: efficace Ta | E14: efficace Pb | F14: transmise collimateur | G14: transmise jupe | H14: efficace Si | I14: efficace Cd | J14: détecteur
B15: keV | C15: cm2 | D15: (cm2/g) | E15: (cm2/g) | H15: (cm2/g) | I15: (cm2/g) | K15: ph/s/cm2/keV/str | L15: Cts/s/keV | M15: Cts/s/keV | N15: Cts/s/keV | O15: ph/s/keV/cm2 | P15: erg/s/cm2
B16: 50 | C16: 3500 | D16: 5.718 | E16: 8.042 | F16: =EXP(-$C$5*$C$6*E16) -> 2.7559763e-08 | G16: =EXP(-1*D16*$C$5*$C$7) -> 0.38595017 | H16: 0.4385 | I16: 10.67 | J16: 0.998378 | K16: =MIN(167*POWER(B16,-2.38),11.6*POWER(B16,-1.41)) -> 0.015106639 | L16: =K16*$N$10*J16*(MAX(G16*($D$10-$D$8),0)+MAX(G16*F16*($D$9-$D$10),0)+F16*$D$11+$D$12) -> 1.9299384e-11 | M16: =$K$120*0.000084*(B16/10)^(-0.45) -> 2.4835483e-05 | N16: =L16+M16 -> 2.4835503e-05 | O16: =100*$O$5*SQRT(N16)/(C16*J16*SQRT(($O$4*B16)*$O$6))/$L$5 -> 1.7114124e-09 | P16: =O16*B16*B16*0.0000000016021773 -> 6.8549653e-15
B17: =B16+6.5 -> 56.5 | C17: 6800 | D17: 4.164 | E17: 5.859 | F17: =EXP(-$C$5*$C$6*E17) -> 3.1071474e-06 | G17: =EXP(-1*D17*$C$5*$C$7) -> 0.4999206 | H17: 0.3529 | I17: 7.688 | J17: 0.97818406 | K17: =MIN(167*POWER(B17,-2.38),11.6*POWER(B17,-1.41)) -> 0.011293828 | L17: =K17*$N$10*J17*(MAX(G17*($D$10-$D$8),0)+MAX(G17*F17*($D$9-$D$10),0)+F17*$D$11+$D$12) -> 1.5944665e-09 | M17: =$K$120*0.000084*(B17/10)^(-0.45) -> 2.3506465e-05 | N17: =L17+M17 -> 2.3508059e-05 | O17: =100*$O$5*SQRT(N17)/(C17*J17*SQRT(($O$4*B17)*$O$6))/$L$5 -> 8.2285046e-10 | P17: =O17*B17*B17*0.0000000016021773 -> 4.2085102e-15
B18: =B17+6.5 -> 63 | C18: 10100 | D18: 3.15 | E18: 4.428 | F18: =EXP(-$C$5*$C$6*E18) -> 6.8793176e-05 | G18: =EXP(-1*D18*$C$5*$C$7) -> 0.59186601 | H18: 0.2982 | I18: 5.738 | J18: 0.95799012 | K18: =MIN(167*POWER(B18,-2.38),11.6*POWER(B18,-1.41)) -> 0.0087153727 | L18: =K18*$N$10*J18*(MAX(G18*($D$10-$D$8),0)+MAX(G18*F18*($D$9-$D$10),0)+F18*$D$11+$D$12) -> 2.6689147e-08 | M18: =$K$120*0.000084*(B18/10)^(-0.45) -> 2.238236e-05 | N18: =L18+M18 -> 2.2409049e-05 | O18: =100*$O$5*SQRT(N18)/(C18*J18*SQRT(($O$4*B18)*$O$6))/$L$5 -> 5.2302841e-10 | P18: =O18*B18*B18*0.0000000016021773 -> 3.3259595e-15
B19: =B18+6.5 -> 69.5 | C19: 13400 | D19: 10.9 | E19: 3.446 | F19: =EXP(-$C$5*$C$6*E19) -> 0.00057630876 | G19: =EXP(-1*D19*$C$5*$C$7) -> 0.16286234 | H19: 0.2613 | I19: 4.405 | J19: 0.93779618 | K19: =MIN(167*POWER(B19,-2.38),11.6*POWER(B19,-1.41)) -> 0.0068991031 | L19: =K19*$N$10*J19*(MAX(G19*($D$10-$D$8),0)+MAX(G19*F19*($D$9-$D$10),0)+F19*$D$11+$D$12) -> 1.7297996e-07 | M19: =$K$120*0.000084*(B19/10)^(-0.45) -> 2.1414895e-05 | N19: =L19+M19 -> 2.1587875e-05 | O19: =100*$O$5*SQRT(N19)/(C19*J19*SQRT(($O$4*B19)*$O$6))/$L$5 -> 3.7632714e-10 | P19: =O19*B19*B19*0.0000000016021773 -> 2.9123645e-15
B20: =B19+6.5 -> 76 | C20: 16700 | D20: 8.655 | E20: 2.75 | F20: =EXP(-$C$5*$C$6*E20) -> 0.002599659 | G20: =EXP(-1*D20*$C$5*$C$7) -> 0.23667734 | H20: 0.2352 | I20: 3.464 | J20: 0.91760224 | K20: =MIN(167*POWER(B20,-2.38),11.6*POWER(B20,-1.41)) -> 0.0055767365 | L20: =K20*$N$10*J20*(MAX(G20*($D$10-$D$8),0)+MAX(G20*F20*($D$9-$D$10),0)+F20*$D$11+$D$12) -> 6.1732158e-07 | M20: =$K$120*0.000084*(B20/10)^(-0.45) -> 2.0570413e-05 | N20: =L20+M20 -> 2.1187734e-05 | O20: =100*$O$5*SQRT(N20)/(C20*J20*SQRT(($O$4*B20)*$O$6))/$L$5 -> 2.9236863e-10 | P20: =O20*B20*B20*0.0000000016021773 -> 2.7056308e-15
B21: =B20+6.5 -> 82.5 | C21: 20000 | D21: 7.014 | E21: 2.241 | F21: =EXP(-$C$5*$C$6*E21) -> 0.0078233338 | G21: =EXP(-1*D21*$C$5*$C$7) -> 0.31104086 | H21: 0.2161 | I21: 2.78 | J21: 0.8974083 | K21: =MIN(167*POWER(B21,-2.38),11.6*POWER(B21,-1.41)) -> 0.0045872887 | L21: =K21*$N$10*J21*(MAX(G21*($D$10-$D$8),0)+MAX(G21*F21*($D$9-$D$10),0)+F21*$D$11+$D$12) -> 1.4949284e-06 | M21: =$K$120*0.000084*(B21/10)^(-0.45) -> 1.9824619e-05 | N21: =L21+M21 -> 2.1319547e-05 | O21: =100*$O$5*SQRT(N21)/(C21*J21*SQRT(($O$4*B21)*$O$6))/$L$5 -> 2.4033011e-10 | P21: =O21*B21*B21*0.0000000016021773 -> 2.6207564e-15
B22: =B21+6.5 -> 89 | C22: =C21-215 -> 19785 | D22: 5.783 | E22: 7.466 | F22: =EXP(-$C$5*$C$6*E22) -> 9.5881096e-08 | G22: =EXP(-1*D22*$C$5*$C$7) -> 0.38179575 | H22: 0.2015 | I22: 2.272 | J22: 0.87721436 | K22: =MIN(167*POWER(B22,-2.38),11.6*POWER(B22,-1.41)) -> 0.0038297309 | L22: =K22*$N$10*J22*(MAX(G22*($D$10-$D$8),0)+MAX(G22*F22*($D$9-$D$10),0)+F22*$D$11+$D$12) -> 1.495565e-11 | M22: =$K$120*0.000084*(B22/10)^(-0.45) -> 1.9159476e-05 | N22: =L22+M22 -> 1.9159491e-05 | O22: =100*$O$5*SQRT(N22)/(C22*J22*SQRT(($O$4*B22)*$O$6))/$L$5 -> 2.2684094e-10 | P22: =O22*B22*B22*0.0000000016021773 -> 2.8788035e-15
B23: =B22+6.5 -> 95.5 | C23: =C22-215 -> 19570 | D23: 4.835 | E23: 6.237 | F23: =EXP(-$C$5*$C$6*E23) -> 1.3709776e-06 | G23: =EXP(-1*D23*$C$5*$C$7) -> 0.44707563 | H23: 0.1901 | I23: 1.886 | J23: 0.85702042 | K23: =MIN(167*POWER(B23,-2.38),11.6*POWER(B23,-1.41)) -> 0.0032382356 | L23: =K23*$N$10*J23*(MAX(G23*($D$10-$D$8),0)+MAX(G23*F23*($D$9-$D$10),0)+F23*$D$11+$D$12) -> 1.7669946e-10 | M23: =$K$120*0.000084*(B23/10)^(-0.45) -> 1.8561266e-05 | N23: =L23+M23 -> 1.8561443e-05 | O23: =100*$O$5*SQRT(N23)/(C23*J23*SQRT(($O$4*B23)*$O$6))/$L$5 -> 2.2304292e-10 | P23: =O23*B23*B23*0.0000000016021773 -> 3.2591605e-15
B24: =B23+6.5 -> 102 | C24: =C23-215 -> 19355 | D24: 4.089 | E24: 5.278 | F24: =EXP(-$C$5*$C$6*E24) -> 1.0927467e-05 | G24: =EXP(-1*D24*$C$5*$C$7) -> 0.5062025 | H24: 0.1809 | I24: 1.587 | J24: 0.82868944 | K24: =MIN(167*POWER(B24,-2.38),11.6*POWER(B24,-1.41)) -> 0.0027685225 | L24: =K24*$N$10*J24*(MAX(G24*($D$10-$D$8),0)+MAX(G24*F24*($D$9-$D$10),0)+F24*$D$11+$D$12) -> 1.1645589e-09 | M24: =$K$120*0.000084*(B24/10)^(-0.45) -> 1.8019347e-05 | N24: =L24+M24 -> 1.8020511e-05 | O24: =100*$O$5*SQRT(N24)/(C24*J24*SQRT(($O$4*B24)*$O$6))/$L$5 -> 2.2236413e-10 | P24: =O24*B24*B24*0.0000000016021773 -> 3.7065994e-15
B25: =B24+6.5 -> 108.5 | C25: =C24-215 -> 19140 | D25: 3.492 | E25: 4.516 | F25: =EXP(-$C$5*$C$6*E25) -> 5.6862073e-05 | G25: =EXP(-1*D25*$C$5*$C$7) -> 0.55910499 | H25: 0.1734 | I25: 1.352 | J25: 0.78205012 | K25: =MIN(167*POWER(B25,-2.38),11.6*POWER(B25,-1.41)) -> 0.0023899769 | L25: =K25*$N$10*J25*(MAX(G25*($D$10-$D$8),0)+MAX(G25*F25*($D$9-$D$10),0)+F25*$D$11+$D$12) -> 4.9378702e-09 | M25: =$K$120*0.000084*(B25/10)^(-0.45) -> 1.7525311e-05 | N25: =L25+M25 -> 1.7530249e-05 | O25: =100*$O$5*SQRT(N25)/(C25*J25*SQRT(($O$4*B25)*$O$6))/$L$5 -> 2.2786042e-10 | P25: =O25*B25*B25*0.0000000016021773 -> 4.2977283e-15
B26: =B25+6.5 -> 115 | C26: =C25-215 -> 18925 | D26: 3.008 | E26: 3.902 | F26: =EXP(-$C$5*$C$6*E26) -> 0.00021478372 | G26: =EXP(-1*D26*$C$5*$C$7) -> 0.60602624 | H26: 0.1671 | I26: 1.165 | J26: 0.7354108 | K26: =MIN(167*POWER(B26,-2.38),11.6*POWER(B26,-1.41)) -> 0.0020809211 | L26: =K26*$N$10*J26*(MAX(G26*($D$10-$D$8),0)+MAX(G26*F26*($D$9-$D$10),0)+F26*$D$11+$D$12) -> 1.5273989e-08 | M26: =$K$120*0.000084*(B26/10)^(-0.45) -> 1.707242e-05 | N26: =L26+M26 -> 1.7087694e-05 | O26: =100*$O$5*SQRT(N26)/(C26*J26*SQRT(($O$4*B26)*$O$6))/$L$5 -> 2.3501369e-10 | P26: =O26*B26*B26*0.0000000016021773 -> 4.9796569e-15
B27: =B26+6.5 -> 121.5 | C27: =C26-215 -> 18710 | D27: 2.613 | E27: 3.401 | F27: =EXP(-$C$5*$C$6*E27) -> 0.00063526743 | G27: =EXP(-1*D27*$C$5*$C$7) -> 0.64722292 | H27: 0.1617 | I27: 1.014 | J27: 0.68877148 | K27: =MIN(167*POWER(B27,-2.38),11.6*POWER(B27,-1.41)) -> 0.0018256811 | L27: =K27*$N$10*J27*(MAX(G27*($D$10-$D$8),0)+MAX(G27*F27*($D$9-$D$10),0)+F27*$D$11+$D$12) -> 3.712698e-08 | M27: =$K$120*0.000084*(B27/10)^(-0.45) -> 1.6655198e-05 | N27: =L27+M27 -> 1.6692325e-05 | O27: =100*$O$5*SQRT(N27)/(C27*J27*SQRT(($O$4*B27)*$O$6))/$L$5 -> 2.4405493e-10 | P27: =O27*B27*B27*0.0000000016021773 -> 5.7723241e-15
B28: =B27+6.5 -> 128 | C28: =C27-215 -> 18495 | D28: 2.288 | E28: 2.986 | F28: =EXP(-$C$5*$C$6*E28) -> 0.001559801 | G28: =EXP(-1*D28*$C$5*$C$7) -> 0.68321068 | H28: 0.157 | I28: 0.89 | J28: 0.64213216 | K28: =MIN(167*POWER(B28,-2.38),11.6*POWER(B28,-1.41)) -> 0.0016127117 | L28: =K28*$N$10*J28*(MAX(G28*($D$10-$D$8),0)+MAX(G28*F28*($D$9-$D$10),0)+F28*$D$11+$D$12) -> 7.5083104e-08 | M28: =$K$120*0.000084*(B28/10)^(-0.45) -> 1.6269141e-05 | N28: =L28+M28 -> 1.6344225e-05 | O28: =100*$O$5*SQRT(N28)/(C28*J28*SQRT(($O$4*B28)*$O$6))/$L$5 -> 2.5530814e-10 | P28: =O28*B28*B28*0.0000000016021773 -> 6.7018574e-15
B29: =B28+6.5 -> 134.5 | C29: =C28-215 -> 18280 | D29: 2.016 | E29: 2.64 | F29: =EXP(-$C$5*$C$6*E29) -> 0.0032985246 | G29: =EXP(-1*D29*$C$5*$C$7) -> 0.71486326 | H29: 0.1529 | I29: 0.788 | J29: 0.59549284 | K29: =MIN(167*POWER(B29,-2.38),11.6*POWER(B29,-1.41)) -> 0.0014333671 | L29: =K29*$N$10*J29*(MAX(G29*($D$10-$D$8),0)+MAX(G29*F29*($D$9-$D$10),0)+F29*$D$11+$D$12) -> 1.3088725e-07 | M29: =$K$120*0.000084*(B29/10)^(-0.45) -> 1.591051e-05 | N29: =L29+M29 -> 1.6041397e-05 | O29: =100*$O$5*SQRT(N29)/(C29*J29*SQRT(($O$4*B29)*$O$6))/$L$5 -> 2.6919901e-10 | P29: =O29*B29*B29*0.0000000016021773 -> 7.8024071e-15
B30: =B29+6.5 -> 141 | C30: =C29-215 -> 18065 | D30: 1.789 | E30: 2.348 | F30: =EXP(-$C$5*$C$6*E30) -> 0.0062059548 | G30: =EXP(-1*D30*$C$5*$C$7) -> 0.74239896 | H30: 0.1493 | I30: 0.7031 | J30: 0.54885352 | K30: =MIN(167*POWER(B30,-2.38),11.6*POWER(B30,-1.41)) -> 0.0012810763 | L30: =K30*$N$10*J30*(MAX(G30*($D$10-$D$8),0)+MAX(G30*F30*($D$9-$D$10),0)+F30*$D$11+$D$12) -> 2.028751e-07 | M30: =$K$120*0.000084*(B30/10)^(-0.45) -> 1.5576164e-05 | N30: =L30+M30 -> 1.5779039e-05 | O30: =100*$O$5*SQRT(N30)/(C30*J30*SQRT(($O$4*B30)*$O$6))/$L$5 -> 2.8628761e-10 | P30: =O30*B30*B30*0.0000000016021773 -> 9.1190869e-15
B31: =B30+6.5 -> 147.5 | C31: =C30-215 -> 17850 | D31: 1.597 | E31: 2.1 | F31: =EXP(-$C$5*$C$6*E31) -> 0.010615395 | G31: =EXP(-1*D31*$C$5*$C$7) -> 0.76651539 | H31: 0.146 | I31: 0.6316 | J31: 0.5022142 | K31: =MIN(167*POWER(B31,-2.38),11.6*POWER(B31,-1.41)) -> 0.0011507778 | L31: =K31*$N$10*J31*(MAX(G31*($D$10-$D$8),0)+MAX(G31*F31*($D$9-$D$10),0)+F31*$D$11+$D$12) -> 2.8526254e-07 | M31: =$K$120*0.000084*(B31/10)^(-0.45) -> 1.526345e-05 | N31: =L31+M31 -> 1.5548713e-05 | O31: =100*$O$5*SQRT(N31)/(C31*J31*SQRT(($O$4*B31)*$O$6))/$L$5 -> 3.0731959e-10 | P31: =O31*B31*B31*0.0000000016021773 -> 1.0712353e-14
B32: =B31+6.5 -> 154 | C32: =C31-215 -> 17635 | D32: 1.433 | E32: 1.888 | F32: =EXP(-$C$5*$C$6*E32) -> 0.016796647 | G32: =EXP(-1*D32*$C$5*$C$7) -> 0.78773424 | H32: 0.143 | I32: 0.5712 | J32: 0.4693976 | K32: =MIN(167*POWER(B32,-2.38),11.6*POWER(B32,-1.41)) -> 0.0010385255 | L32: =K32*$N$10*J32*(MAX(G32*($D$10-$D$8),0)+MAX(G32*F32*($D$9-$D$10),0)+F32*$D$11+$D$12) -> 3.8075312e-07 | M32: =$K$120*0.000084*(B32/10)^(-0.45) -> 1.4970103e-05 | N32: =L32+M32 -> 1.5350856e-05 | O32: =100*$O$5*SQRT(N32)/(C32*J32*SQRT(($O$4*B32)*$O$6))/$L$5 -> 3.2363528e-10 | P32: =O32*B32*B32*0.0000000016021773 -> 1.2297247e-14
B33: =B32+6.5 -> 160.5 | C33: =C32-215 -> 17420 | D33: 1.293 | E33: 1.704 | F33: =EXP(-$C$5*$C$6*E33) -> 0.02501429 | G33: =EXP(-1*D33*$C$5*$C$7) -> 0.80631201 | H33: 0.1403 | I33: 0.5195 | J33: 0.4452202 | K33: =MIN(167*POWER(B33,-2.38),11.6*POWER(B33,-1.41)) -> 0.00094120859 | L33: =K33*$N$10*J33*(MAX(G33*($D$10-$D$8),0)+MAX(G33*F33*($D$9-$D$10),0)+F33*$D$11+$D$12) -> 4.8746359e-07 | M33: =$K$120*0.000084*(B33/10)^(-0.45) -> 1.469418e-05 | N33: =L33+M33 -> 1.5181644e-05 | O33: =100*$O$5*SQRT(N33)/(C33*J33*SQRT(($O$4*B33)*$O$6))/$L$5 -> 3.3648454e-10 | P33: =O33*B33*B33*0.0000000016021773 -> 1.3887554e-14
... B80: =B79+6.5 -> 466 | C80: =C79-215 -> 7315 | D80: 0.1491 | E80: 0.1799 | F80: =EXP(-$C$5*$C$6*E80) -> 0.6774676 | G80: =EXP(-1*D80*$C$5*$C$7) -> 0.97548046 | H80: 0.09016 | I80: 0.09884 | J80: 0 | K80: =MIN(167*POWER(B80,-2.38),11.6*POWER(B80,-1.41)) -> 7.4465994e-05 | L80: =K80*$N$10*J80*(MAX(G80*($D$10-$D$8),0)+MAX(G80*F80*($D$9-$D$10),0)+F80*$D$11+$D$12) -> 0 | M80: =$K$120*0.000084*(B80/10)^(-0.45) -> 9.095686e-06 | N80: =L80+M80 -> 9.095686e-06 | O80: =100*$O$5*SQRT(N80)/(C80*J80*SQRT(($O$4*B80)*$O$6))/$L$5 -> #DIV/0! | P80: =O80*B80*B80*0.0000000016021773 -> #DIV/0!
B81: =B80+6.5 -> 472.5 | C81: =C80-215 -> 7100 | D81: 0.1462 | E81: 0.176 | F81: =EXP(-$C$5*$C$6*E81) -> 0.68321068 | G81: =EXP(-1*D81*$C$5*$C$7) -> 0.97595158 | H81: 0.08963 | I81: 0.09761 | J81: =J80 -> 0 | K81: =MIN(167*POWER(B81,-2.38),11.6*POWER(B81,-1.41)) -> 7.2051024e-05 | L81: =K81*$N$10*J81*(MAX(G81*($D$10-$D$8),0)+MAX(G81*F81*($D$9-$D$10),0)+F81*$D$11+$D$12) -> 0 | M81: =$K$120*0.000084*(B81/10)^(-0.45) -> 9.0391648e-06 | N81: =L81+M81 -> 9.0391648e-06 | O81: =100*$O$5*SQRT(N81)/(C81*J81*SQRT(($O$4*B81)*$O$6))/$L$5 -> #DIV/0! | P81: =O81*B81*B81*0.0000000016021773 -> #DIV/0!
B82: =B81+6.5 -> 479 | C82: =C81-215 -> 6885 | D82: 0.1434 | E82: 0.1723 | F82: =EXP(-$C$5*$C$6*E82) -> 0.68870425 | G82: =EXP(-1*D82*$C$5*$C$7) -> 0.97640668 | H82: 0.08911 | I82: 0.09643 | J82: =J81 -> 0 | K82: =MIN(167*POWER(B82,-2.38),11.6*POWER(B82,-1.41)) -> 6.9745782e-05 | L82: =K82*$N$10*J82*(MAX(G82*($D$10-$D$8),0)+MAX(G82*F82*($D$9-$D$10),0)+F82*$D$11+$D$12) -> 0 | M82: =$K$120*0.000084*(B82/10)^(-0.45) -> 8.98376e-06 | N82: =L82+M82 -> 8.98376e-06 | O82: =100*$O$5*SQRT(N82)/(C82*J82*SQRT(($O$4*B82)*$O$6))/$L$5 -> #DIV/0! | P82: =O82*B82*B82*0.0000000016021773 -> #DIV/0!
B83: =B82+6.5 -> 485.5 | C83: =C82-215 -> 6670 | D83: 0.1408 | E83: 0.1688 | F83: =EXP(-$C$5*$C$6*E83) -> 0.69394151 | G83: =EXP(-1*D83*$C$5*$C$7) -> 0.97682946 | H83: 0.08859 | I83: 0.0953 | J83: =J82 -> 0 | K83: =MIN(167*POWER(B83,-2.38),11.6*POWER(B83,-1.41)) -> 6.7543894e-05 | L83: =K83*$N$10*J83*(MAX(G83*($D$10-$D$8),0)+MAX(G83*F83*($D$9-$D$10),0)+F83*$D$11+$D$12) -> 0 | M83: =$K$120*0.000084*(B83/10)^(-0.45) -> 8.9294347e-06 | N83: =L83+M83 -> 8.9294347e-06 | O83: =100*$O$5*SQRT(N83)/(C83*J83*SQRT(($O$4*B83)*$O$6))/$L$5 -> #DIV/0! | P83: =O83*B83*B83*0.0000000016021773 -> #DIV/0!
B84: =B83+6.5 -> 492 | C84: =C83-215 -> 6455 | D84: 0.1382 | E84: 0.1653 | F84: =EXP(-$C$5*$C$6*E84) -> 0.6992186 | G84: =EXP(-1*D84*$C$5*$C$7) -> 0.97725242 | H84: 0.08809 | I84: 0.09421 | J84: =J83 -> 0 | K84: =MIN(167*POWER(B84,-2.38),11.6*POWER(B84,-1.41)) -> 6.5439433e-05 | L84: =K84*$N$10*J84*(MAX(G84*($D$10-$D$8),0)+MAX(G84*F84*($D$9-$D$10),0)+F84*$D$11+$D$12) -> 0 | M84: =$K$120*0.000084*(B84/10)^(-0.45) -> 8.8761539e-06 | N84: =L84+M84 -> 8.8761539e-06 | O84: =100*$O$5*SQRT(N84)/(C84*J84*SQRT(($O$4*B84)*$O$6))/$L$5 -> #DIV/0! | P84: =O84*B84*B84*0.0000000016021773 -> #DIV/0!
B85: =B84+6.5 -> 498.5 | C85: =C84-215 -> 6240 | D85: 0.1358 | E85: 0.1621 | F85: =EXP(-$C$5*$C$6*E85) -> 0.70407848 | G85: =EXP(-1*D85*$C$5*$C$7) -> 0.97764301 | H85: 0.08759 | I85: 0.09315 | J85: =J84 -> 0 | K85: =MIN(167*POWER(B85,-2.38),11.6*POWER(B85,-1.41)) -> 6.3426885e-05 | L85: =K85*$N$10*J85*(MAX(G85*($D$10-$D$8),0)+MAX(G85*F85*($D$9-$D$10),0)+F85*$D$11+$D$12) -> 0 | M85: =$K$120*0.000084*(B85/10)^(-0.45) -> 8.8238842e-06 | N85: =L85+M85 -> 8.8238842e-06 | O85: =100*$O$5*SQRT(N85)/(C85*J85*SQRT(($O$4*B85)*$O$6))/$L$5 -> #DIV/0! | P85: =O85*B85*B85*0.0000000016021773 -> #DIV/0!
B86: =B85+6.5 -> 505 | C86: =C85-215 -> 6025 | D86: 0.1335 | E86: 0.159 | F86: =EXP(-$C$5*$C$6*E86) -> 0.7088187 | G86: =EXP(-1*D86*$C$5*$C$7) -> 0.97801747 | H86: 0.08711 | I86: 0.09213 | J86: =J85 -> 0 | K86: =MIN(167*POWER(B86,-2.38),11.6*POWER(B86,-1.41)) -> 6.1501115e-05 | L86: =K86*$N$10*J86*(MAX(G86*($D$10-$D$8),0)+MAX(G86*F86*($D$9-$D$10),0)+F86*$D$11+$D$12) -> 0 | M86: =$K$120*0.000084*(B86/10)^(-0.45) -> 8.7725934e-06 | N86: =L86+M86 -> 8.7725934e-06 | O86: =100*$O$5*SQRT(N86)/(C86*J86*SQRT(($O$4*B86)*$O$6))/$L$5 -> #DIV/0! | P86: =O86*B86*B86*0.0000000016021773 -> #DIV/0!
B87: =B86+6.5 -> 511.5 | C87: =C86-215 -> 5810 | D87: 0.1312 | E87: 0.156 | F87: =EXP(-$C$5*$C$6*E87) -> 0.71343639 | G87: =EXP(-1*D87*$C$5*$C$7) -> 0.97839207 | H87: 0.08663 | I87: 0.09115 | J87: =J86 -> 0 | K87: =MIN(167*POWER(B87,-2.38),11.6*POWER(B87,-1.41)) -> 5.9657336e-05 | L87: =K87*$N$10*J87*(MAX(G87*($D$10-$D$8),0)+MAX(G87*F87*($D$9-$D$10),0)+F87*$D$11+$D$12) -> 0 | M87: =$K$120*0.000084*(B87/10)^(-0.45) -> 8.7222511e-06 | N87: =L87+M87 -> 8.7222511e-06 | O87: =100*$O$5*SQRT(N87)/(C87*J87*SQRT(($O$4*B87)*$O$6))/$L$5 -> #DIV/0! | P87: =O87*B87*B87*0.0000000016021773 -> #DIV/0!
B88: =B87+6.5 -> 518 | C88: =C87-215 -> 5595 | D88: 0.129 | E88: 0.1531 | F88: =EXP(-$C$5*$C$6*E88) -> 0.71792875 | G88: =EXP(-1*D88*$C$5*$C$7) -> 0.97875052 | H88: 0.08616 | I88: 0.0902 | J88: =J87 -> 0 | K88: =MIN(167*POWER(B88,-2.38),11.6*POWER(B88,-1.41)) -> 5.7891079e-05 | L88: =K88*$N$10*J88*(MAX(G88*($D$10-$D$8),0)+MAX(G88*F88*($D$9-$D$10),0)+F88*$D$11+$D$12) -> 0 | M88: =$K$120*0.000084*(B88/10)^(-0.45) -> 8.6728279e-06 | N88: =L88+M88 -> 8.6728279e-06 | O88: =100*$O$5*SQRT(N88)/(C88*J88*SQRT(($O$4*B88)*$O$6))/$L$5 -> #DIV/0! | P88: =O88*B88*B88*0.0000000016021773 -> #DIV/0!
...

Sheet MDP
F2: MDP (LENTILLE) | L2: version 1.0
B6: densité Si | C6: 1 | D6: g/cm3 | H6: Tobs | I6: 1000000 | J6: s
B7: densité CdTe | C7: 6.2 | D7: g/cm3 | H7: Fluence | I7: 1e-09 | J7: erg/cm2/s
B8: épaisseur Si | C8: 0.045 | D8: cm | O8: energy band | P8: Mean Energy | Q8: Crabe fluence | R8: mean mu_100 | S8: Crab MDP | T8: Source MDP
B9: épaisseur CdTe | C9: 0.2 | D9: cm
O11: 40-50 keV | P11: 45 | Q11: =SUM(I17:I26)*6.5 -> 8.5870079e-07 | R11: =SUM(L26:L30)/5 -> 0.3 | S11: =4.29/R11/SUM(J17:J26)*SQRT((SUM(J17:J26)+SUM(K17:K26)*6.5)/$I$6) -> 0.015638595 | T11: =4.29/R11/SUM(J17:J26)*Q11/$I$7*SQRT((SUM(J17:J26)*$I$7/Q11+SUM(K17:K26)*6.5)/$I$6) -> 0.65589844
O12: 50-76 keV | P12: 63 | Q12: =SUM(I27:I31)*6.5 -> 4.2294478e-07 | R12: =SUM(L17:L26)/10 -> 0.3 | S12: =4.29/R12/SUM(J27:J31)*SQRT((SUM(J27:J31)+SUM(K27:K31)*6.5)/$I$6) -> 0.0057577889 | T12: =4.29/R12/SUM(J27:J31)*Q12/$I$7*SQRT((SUM(J27:J31)*$I$7/Q12+SUM(K27:K31)*6.5)/$I$6) -> 0.1213637
O13: 76-102 keV | P13: 89 | Q13: =SUM(I31:I35)*6.5 -> 4.1558188e-07 | R13: =SUM(L31:L35)/5 -> 0.3 | S13: =4.29/R13/SUM(J31:J35)*SQRT((SUM(J31:J35)+SUM(K31:K35)*6.5)/$I$6) -> 0.005824826 | T13: =4.29/R13/SUM(J31:J35)*Q13/$I$7*SQRT((SUM(J31:J35)*$I$7/Q13+SUM(K31:K35)*6.5)/$I$6) -> 0.12132342
B14: Energie | C14: Surface | D14: Section | E14: Section | F14: efficacité | G14: efficacité | H14: Crabe | I14: Crabe | J14: Crabe total | K14: Bruit total | L14: MDP | O14: 102-154 keV | P14: 128 | Q14: =SUM(I35:I43)*6.5 -> 7.3470751e-07 | R14: =SUM(L35:L43)/9 -> 0.3 | S14: =4.29/R14/SUM(J35:J43)*SQRT((SUM(J35:J43)+SUM(K35:K43)*6.5)/$I$6) -> 0.0072135506 | T14: =4.29/R14/SUM(J35:J43)*Q14/$I$7*SQRT((SUM(J35:J43)*$I$7/Q14+SUM(K35:K43)*6.5)/$I$6) -> 0.21239634
C15: mirroir | D15: efficace Si | E15: efficace Cd | F15: détecteur | G15: Compton | O15: 154-206 keV | P15: 180 | Q15: =SUM(I43:I51)*6.5 -> 7.2212457e-07 | R15: =SUM(L43:L51)/9 -> 0.3 | S15: =4.29/R15/SUM(J43:J51)*SQRT((SUM(J43:J51)+SUM(K43:K51)*6.5)/$I$6) -> 0.014221872 | T15: =4.29/R15/SUM(J43:J51)*Q15/$I$7*SQRT((SUM(J43:J51)*$I$7/Q15+SUM(K43:K51)*6.5)/$I$6) -> 0.48533524
B16: keV | C16: cm2 | D16: (cm2/g) | E16: (cm2/g) | H16: ph/s/cm2/keV | I16: erg/cm2/s | J16: Cts/s | K16: ='Calculs lentille'!N15 -> Cts/s/keV | L16: mu_100 | M16: MDP (%) | O16: 206-258 keV | P16: =P15+52 -> 232 | Q16: =SUM(I51:I59)*6.5 -> 7.1295381e-07 | R16: =SUM(L51:L59)/9 -> 0.3 | S16: =4.29/R16/SUM(J51:J59)*SQRT((SUM(J51:J59)+SUM(K51:K59)*6.5)/$I$6) -> 0.024194196 | T16: =4.29/R16/SUM(J51:J59)*Q16/$I$7*SQRT((SUM(J51:J59)*$I$7/Q16+SUM(K51:K59)*6.5)/$I$6) -> 1.039826
B17: 42.560606 | C17: 330 | D17: 0.61 | E17: 15.98 | F17: =1-EXP(-D17*$C$6*$C$8)*EXP(-E17*$C$7*$C$9) -> 1 | G17: 0.01 | H17: =10*POWER(B17,-2.05) -> 0.0045765056 | I17: =0.0000000016*B17*B17*H17 -> 1.326385e-08 | J17: =H17*6.5*C17*F17*G17 -> 0.098166046 | K17: ='Calculs mirroir'!N68 -> 1.6323976e-05 | L17: 0.3 | M17: =4.29/0.3/SQRT(J17) -> 45.641025 | O17: 258-310 keV | P17: 284 | Q17: =SUM(I59:I67)*6.5 -> 7.0574835e-07 | R17: =SUM(L59:L67)/9 -> 0.3 | S17: =4.29/R17/SUM(J59:J67)*SQRT((SUM(J59:J67)+SUM(K59:K67)*6.5)/$I$6) -> 0.036841419 | T17: =4.29/R17/SUM(J59:J67)*Q17/$I$7*SQRT((SUM(J59:J67)*$I$7/Q17+SUM(K59:K67)*6.5)/$I$6) -> 2.0277159
B18: 43.363636 | C18: 330 | D18: 0.586 | E18: 15.2 | F18: =1-EXP(-D18*$C$6*$C$8)*EXP(-E18*$C$7*$C$9) -> 0.99999999 | G18: 0.01 | H18: =10*POWER(B18,-2.05) -> 0.0044044565 | I18: =0.0000000016*B18*B18*H18 -> 1.3251459e-08 | J18: =H18*6.5*C18*F18*G18 -> 0.094475592 | K18: ='Calculs mirroir'!N69 -> 1.6191664e-05 | L18: 0.3 | M18: =4.29/0.3/SQRT(J18) -> 46.523912 | O18: 310-362 keV | P18: =P17+52 -> 336 | Q18: =SUM(I67:I75)*6.5 -> 6.9982168e-07 | R18: =SUM(L67:L75)/9 -> 0.3 | S18: =4.29/R18/SUM(J67:J75)*SQRT((SUM(J67:J75)+SUM(K67:K75)*6.5)/$I$6) -> 0.052301776 | T18: =4.29/R18/SUM(J67:J75)*Q18/$I$7*SQRT((SUM(J67:J75)*$I$7/Q18+SUM(K67:K75)*6.5)/$I$6) -> 3.653345
B19: 44.166667 | C19: 330 | D19: 0.563 | E19: 14.47 | F19: =1-EXP(-D19*$C$6*$C$8)*EXP(-E19*$C$7*$C$9) -> 0.99999998 | G19: 0.01 | H19: =10*POWER(B19,-2.05) -> 0.004241857 | I19: =0.0000000016*B19*B19*H19 -> 1.3239307e-08 | J19: =H19*6.5*C19*F19*G19 -> 0.090987831 | K19: ='Calculs mirroir'!N70 -> 1.6062477e-05 | L19: 0.3 | M19: =4.29/0.3/SQRT(J19) -> 47.407208 | O19: 362-414 keV | P19: 388 | Q19: =SUM(I75:I83)*6.5 -> 6.9479331e-07 | R19: =SUM(L75:L83)/9 -> 0.3 | S19: =4.29/R19/SUM(J75:J83)*SQRT((SUM(J75:J83)+SUM(K75:K83)*6.5)/$I$6) -> 0.071243296 | T19: =4.29/R19/SUM(J75:J83)*Q19/$I$7*SQRT((SUM(J75:J83)*$I$7/Q19+SUM(K75:K83)*6.5)/$I$6) -> 6.2156299
B20: 44.969697 | C20: 330 | D20: 0.542 | E20: 13.78 | F20: =1-EXP(-D20*$C$6*$C$8)*EXP(-E20*$C$7*$C$9) -> 0.99999996 | G20: 0.01 | H20: =10*POWER(B20,-2.05) -> 0.00408803 | I20: =0.0000000016*B20*B20*H20 -> 1.3227385e-08 | J20: =H20*6.5*C20*F20*G20 -> 0.087688241 | K20: ='Calculs mirroir'!N71 -> 1.5936217e-05 | L20: 0.3 | M20: =4.29/0.3/SQRT(J20) -> 48.290906
B21: 45.772727 | C21: 330 | D21: 0.522 | E21: 13.14 | F21: =1-EXP(-D21*$C$6*$C$8)*EXP(-E21*$C$7*$C$9) -> 0.99999992 | G21: 0.01 | H21: =10*POWER(B21,-2.05) -> 0.0039423582 | I21: =0.0000000016*B21*B21*H21 -> 1.3215684e-08 | J21: =H21*6.5*C21*F21*G21 -> 0.084563576 | K21: ='Calculs mirroir'!N72 -> 1.5812932e-05 | L21: 0.3 | M21: =4.29/0.3/SQRT(J21) -> 49.175
B22: 46.575758 | C22: 330 | D22: 0.504 | E22: 12.54 | F22: =1-EXP(-D22*$C$6*$C$8)*EXP(-E22*$C$7*$C$9) -> 0.99999983 | G22: 0.01 | H22: =10*POWER(B22,-2.05) -> 0.0038042771 | I22: =0.0000000016*B22*B22*H22 -> 1.3204197e-08 | J22: =H22*6.5*C22*F22*G22 -> 0.081601731 | K22: ='Calculs mirroir'!N73 -> 1.5692465e-05 | L22: 0.3 | M22: =4.29/0.3/SQRT(J22) -> 50.059482
B23: 47.378788 | C23: 330 | D23: 0.487 | E23: 11.97 | F23: =1-EXP(-D23*$C$6*$C$8)*EXP(-E23*$C$7*$C$9) -> 0.99999965 | G23: 0.01 | H23: =10*POWER(B23,-2.05) -> 0.0036732705 | I23: =0.0000000016*B23*B23*H23 -> 1.3192916e-08 | J23: =H23*6.5*C23*F23*G23 -> 0.078791625 | K23: ='Calculs mirroir'!N74 -> 1.5574666e-05 | L23: 0.3 | M23: =4.29/0.3/SQRT(J23) -> 50.944348
B24: 48.181818 | C24: 330 | D24: 0.471 | E24: 11.44 | F24: =1-EXP(-D24*$C$6*$C$8)*EXP(-E24*$C$7*$C$9) -> 0.99999932 | G24: 0.01 | H24: =10*POWER(B24,-2.05) -> 0.0035488649 | I24: =0.0000000016*B24*B24*H24 -> 1.3181834e-08 | J24: =H24*6.5*C24*F24*G24 -> 0.076123101 | K24: ='Calculs mirroir'!N75 -> 1.54594e-05 | L24: 0.3 | M24: =4.29/0.3/SQRT(J24) -> 51.829593
B25: 48.984848 | C25: 330 | D25: 0.456 | E25: 10.94 | F25: =1-EXP(-D25*$C$6*$C$8)*EXP(-E25*$C$7*$C$9) -> 0.99999874 | G25: 0.01 | H25: =10*POWER(B25,-2.05) -> 0.003430626 | I25: =0.0000000016*B25*B25*H25 -> 1.3170944e-08 | J25: =H25*6.5*C25*F25*G25 -> 0.073586835 | K25: ='Calculs mirroir'!N76 -> 1.5346776e-05 | L25: 0.3 | M25: =4.29/0.3/SQRT(J25) -> 52.715214
B26: 49.787879 | C26: 330 | D26: 0.442 | E26: 10.47 | F26: =1-EXP(-D26*$C$6*$C$8)*EXP(-E26*$C$7*$C$9) -> 0.99999775 | G26: 0.01 | H26: =10*POWER(B26,-2.05) -> 0.0033181543 | I26: =0.0000000016*B26*B26*H26 -> 1.316024e-08 | J26: =H26*6.5*C26*F26*G26 -> 0.071174248 | K26: ='Calculs mirroir'!N77 -> 1.5236443e-05 | L26: 0.3 | M26: =4.29/0.3/SQRT(J26) -> 53.60121
B27: 50 | C27: 3500 | D27: 0.4385 | E27: 10.67 | F27: =1-EXP(-D27*$C$6*$C$8)*EXP(-E27*$C$7*$C$9) -> 0.99999824 | G27: 0.01 | H27: =10*POWER(B27,-2.05) -> 0.0032893606 | I27: =0.0000000016*B27*B27*H27 -> 1.3157443e-08 | J27: =H27*6.5*C27*F27*G27 -> 0.74832823 | K27: ='Calculs lentille'!N16 -> 2.4835503e-05 | L27: 0.3 | M27: =4.29/0.3/SQRT(J27) -> 16.530652
B28: =B27+6.5 -> 56.5 | C28: 6800 | D28: 0.3529 | E28: 7.688 | F28: =1-EXP(-D28*$C$6*$C$8)*EXP(-E28*$C$7*$C$9) -> 0.99992873 | G28: 0.01 | H28: =10*POWER(B28,-2.05) -> 0.0025603579 | I28: =0.0000000016*B28*B28*H28 -> 1.3077284e-08 | J28: =H28*6.5*C28*F28*G28 -> 1.1315975 | K28: ='Calculs lentille'!N17 -> 2.3508059e-05 | L28: 0.3 | M28: =4.29/0.3/SQRT(J28) -> 13.442809
B29: =B28+6.5 -> 63 | C29: 10100 | D29: 0.2982 | E29: 5.738 | F29: =1-EXP(-D29*$C$6*$C$8)*EXP(-E29*$C$7*$C$9) -> 0.99919811 | G29: 0.01 | H29: =10*POWER(B29,-2.05) -> 0.0020481034 | I29: =0.0000000016*B29*B29*H29 -> 1.3006276e-08 | J29: =H29*6.5*C29*F29*G29 -> 1.3435017 | K29: ='Calculs lentille'!N18 -> 2.2409049e-05 | L29: 0.3 | M29: =4.29/0.3/SQRT(J29) -> 12.337209
B30: =B29+6.5 -> 69.5 | C30: 13400 | D30: 0.2613 | E30: 4.405 | F30: =1-EXP(-D30*$C$6*$C$8)*EXP(-E30*$C$7*$C$9) -> 0.99580541 | G30: 0.01 | H30: =10*POWER(B30,-2.05) -> 0.0016746774 | I30: =0.0000000016*B30*B30*H30 -> 1.2942577e-08 | J30: =H30*6.5*C30*F30*G30 -> 1.4525256 | K30: ='Calculs lentille'!N19 -> 2.1587875e-05 | L30: 0.3 | M30: =4.29/0.3/SQRT(J30) -> 11.865175
B31: =B30+6.5 -> 76 | C31: 16700 | D31: 0.2352 | E31: 3.464 | F31: =1-EXP(-D31*$C$6*$C$8)*EXP(-E31*$C$7*$C$9) -> 0.98651185 | G31: 0.01 | H31: =10*POWER(B31,-2.05) -> 0.0013942227 | I31: =0.0000000016*B31*B31*H31 -> 1.2884848e-08 | J31: =H31*6.5*C31*F31*G31 -> 1.4930153 | K31: ='Calculs lentille'!N20 -> 2.1187734e-05 | L31: 0.3 | M31: =4.29/0.3/SQRT(J31) -> 11.70318
B32: =B31+6.5 -> 82.5 | C32: 20000 | D32: 0.2161 | E32: 2.78 | F32: =1-EXP(-D32*$C$6*$C$8)*EXP(-E32*$C$7*$C$9) -> 0.96847343 | G32: 0.01 | H32: =10*POWER(B32,-2.05) -> 0.0011783367 | I32: =0.0000000016*B32*B32*H32 -> 1.2832087e-08 | J32: =H32*6.5*C32*F32*G32 -> 1.4835441 | K32: ='Calculs lentille'!N21 -> 2.1319547e-05 | L32: 0.3 | M32: =4.29/0.3/SQRT(J32) -> 11.740479
B33: =B32+6.5 -> 89 | C33: =C32-215 -> 19785 | D33: 0.2015 | E33: 2.272 | F33: =1-EXP(-D33*$C$6*$C$8)*EXP(-E33*$C$7*$C$9) -> 0.94077121 | G33: 0.01 | H33: =10*POWER(B33,-2.05) -> 0.0010086732 | I33: =0.0000000016*B33*B33*H33 -> 1.2783521e-08 | J33: =H33*6.5*C33*F33*G33 -> 1.2203486 | K33: ='Calculs lentille'!N22 -> 1.9159491e-05 | L33: 0.3 | M33: =4.29/0.3/SQRT(J33) -> 12.944762
B34: =B33+6.5 -> 95.5 | C34: =C33-215 -> 19570 | D34: 0.1901 | E34: 1.886 | F34: =1-EXP(-D34*$C$6*$C$8)*EXP(-E34*$C$7*$C$9) -> 0.9043629 | G34: 0.01 | H34: =10*POWER(B34,-2.05) -> 0.00087295748 | I34: =0.0000000016*B34*B34*H34 -> 1.2738545e-08 | J34: =H34*6.5*C34*F34*G34 -> 1.0042458 | K34: ='Calculs lentille'!N23 -> 1.8561443e-05 | L34: 0.3 | M34: =4.29/0.3/SQRT(J34) -> 14.269739
B35: =B34+6.5 -> 102 | C35: =C34-215 -> 19355 | D35: 0.1809 | E35: 1.587 | F35: =1-EXP(-D35*$C$6*$C$8)*EXP(-E35*$C$7*$C$9) -> 0.86138022 | G35: 0.01 | H35: =10*POWER(B35,-2.05) -> 0.00076272793 | I35: =0.0000000016*B35*B35*H35 -> 1.2696674e-08 | J35: =H35*6.5*C35*F35*G35 -> 0.8265537 | K35: ='Calculs lentille'!N24 -> 1.8020511e-05 | L35: 0.3 | M35: =4.29/0.3/SQRT(J35) -> 15.728978
B36: =B35+6.5 -> 108.5 | C36: =C35-215 -> 19140 | D36: 0.1734 | E36: 1.352 | F36: =1-EXP(-D36*$C$6*$C$8)*EXP(-E36*$C$7*$C$9) -> 0.81442256 | G36: 0.01 | H36: =10*POWER(B36,-2.05) -> 0.00067199963 | I36: =0.0000000016*B36*B36*H36 -> 1.2657516e-08 | J36: =H36*6.5*C36*F36*G36 -> 0.68088555 | K36: ='Calculs lentille'!N25 -> 1.7530249e-05 | L36: 0.3 | M36: =4.29/0.3/SQRT(J36) -> 17.330017
B37: =B36+6.5 -> 115 | C37: =C36-215 -> 18925 | D37: 0.1671 | E37: 1.165 | F37: =1-EXP(-D37*$C$6*$C$8)*EXP(-E37*$C$7*$C$9) -> 0.76592636 | G37: 0.01 | H37: =10*POWER(B37,-2.05) -> 0.00059644366 | I37: =0.0000000016*B37*B37*H37 -> 1.2620748e-08 | J37: =H37*6.5*C37*F37*G37 -> 0.56196037 | K37: ='Calculs lentille'!N26 -> 1.7087694e-05 | L37: 0.3 | M37: =4.29/0.3/SQRT(J37) -> 19.075819
B38: =B37+6.5 -> 121.5 | C38: =C37-215 -> 18710 | D38: 0.1617 | E38: 1.014 | F38: =1-EXP(-D38*$C$6*$C$8)*EXP(-E38*$C$7*$C$9) -> 0.71765809 | G38: 0.01 | H38: =10*POWER(B38,-2.05) -> 0.00053286676 | I38: =0.0000000016*B38*B38*H38 -> 1.25861e-08 | J38: =H38*6.5*C38*F38*G38 -> 0.46507539 | K38: ='Calculs lentille'!N27 -> 1.6692325e-05 | L38: 0.3 | M38: =4.29/0.3/SQRT(J38) -> 20.968838
B39: =B38+6.5 -> 128 | C39: =C38-215 -> 18495 | D39: 0.157 | E39: 0.89 | F39: =1-EXP(-D39*$C$6*$C$8)*EXP(-E39*$C$7*$C$9) -> 0.67066012 | G39: 0.01 | H39: =10*POWER(B39,-2.05) -> 0.00047887213 | I39: =0.0000000016*B39*B39*H39 -> 1.2553346e-08 | J39: =H39*6.5*C39*F39*G39 -> 0.38609105 | K39: ='Calculs lentille'!N28 -> 1.6344225e-05 | L39: 0.3 | M39: =4.29/0.3/SQRT(J39) -> 23.01395
B40: =B39+6.5 -> 134.5 | C40: =C39-215 -> 18280 | D40: 0.1529 | E40: 0.788 | F40: =1-EXP(-D40*$C$6*$C$8)*EXP(-E40*$C$7*$C$9) -> 0.62618733 | G40: 0.01 | H40: =10*POWER(B40,-2.05) -> 0.00043263268 | I40: =0.0000000016*B40*B40*H40 -> 1.2522293e-08 | J40: =H40*6.5*C40*F40*G40 -> 0.32189419 | K40: ='Calculs lentille'!N29 -> 1.6041397e-05 | L40: 0.3 | M40: =4.29/0.3/SQRT(J40) -> 25.20458
B41: =B40+6.5 -> 141 | C41: =C40-215 -> 18065 | D41: 0.1493 | E41: 0.7031 | F41: =1-EXP(-D41*$C$6*$C$8)*EXP(-E41*$C$7*$C$9) -> 0.58462041 | G41: 0.01 | H41: =10*POWER(B41,-2.05) -> 0.0003927361 | I41: =0.0000000016*B41*B41*H41 -> 1.2492778e-08 | J41: =H41*6.5*C41*F41*G41 -> 0.26960387 | K41: ='Calculs lentille'!N30 -> 1.5779039e-05 | L41: 0.3 | M41: =4.29/0.3/SQRT(J41) -> 27.540574
B42: =B41+6.5 -> 147.5 | C42: =C41-215 -> 17850 | D42: 0.146 | E42: 0.6316 | F42: =1-EXP(-D42*$C$6*$C$8)*EXP(-E42*$C$7*$C$9) -> 0.54604355 | G42: 0.01 | H42: =10*POWER(B42,-2.05) -> 0.00035807694 | I42: =0.0000000016*B42*B42*H42 -> 1.2464658e-08 | J42: =H42*6.5*C42*F42*G42 -> 0.22685858 | K42: ='Calculs lentille'!N31 -> 1.5548713e-05 | L42: 0.3 | M42: =4.29/0.3/SQRT(J42) -> 30.0233
B43: =B42+6.5 -> 154 | C43: =C42-215 -> 17635 | D43: 0.143 | E43: 0.5712 | F43: =1-EXP(-D43*$C$6*$C$8)*EXP(-E43*$C$7*$C$9) -> 0.51067236 | G43: 0.01 | H43: =10*POWER(B43,-2.05) -> 0.00032778005 | I43: =0.0000000016*B43*B43*H43 -> 1.2437811e-08 | J43: =H43*6.5*C43*F43*G43 -> 0.19187293 | K43: ='Calculs lentille'!N32 -> 1.5350856e-05 | L43: 0.3 | M43: =4.29/0.3/SQRT(J43) -> 32.645941
B44: =B43+6.5 -> 160.5 | C44: =C43-215 -> 17420 | D44: 0.1403 | E44: 0.5195 | F44: =1-EXP(-D44*$C$6*$C$8)*EXP(-E44*$C$7*$C$9) -> 0.47821179 | G44: 0.01 | H44: =10*POWER(B44,-2.05) -> 0.00030114536 | I44: =0.0000000016*B44*B44*H44 -> 1.2412128e-08 | J44: =H44*6.5*C44*F44*G44 -> 0.16306395 | K44: ='Calculs lentille'!N33 -> 1.5181644e-05 | L44: 0.3 | M44: =4.29/0.3/SQRT(J44) -> 35.412538
... B124: =B123+6.5 -> 680.5 | C124: =C123-215 -> 220 | D124: 0.07633 | E124: 0.07349 | F124: =1-EXP(-D124*$C$6*$C$8)*EXP(-E124*$C$7*$C$9) -> 0.090229082 | G124: 0.01 | H124: =10*POWER(B124,-2.05) -> 1.558484e-05 | I124: =0.0000000016*B124*B124*H124 -> 1.154725e-08 | J124: =H124*6.5*C124*F124*G124 -> 2.0108742e-05 | K124: ='Calculs lentille'!N113 -> 7.6707259e-06 | L124: 0.3 | M124: =4.29/0.3/SQRT(J124) -> 3188.9197
...

Sheet notes
A2: note générale : | B2: la sensibilité est calculée en prenant en compte
B3: l'efficacité des détecteurs, la collimation par le plomb et
B4: le tantale, le bruit interne dans la tache focale. | L4: mirroir
B5: Le fond diffus est donné par :
B6: min(167*E^-2.38;11,6*E^-1,41 ph/cm2/s/keV/str)
B7: Le bruit interne est calculé à partir d'Armstrong et al. 99
B8: et recalé sur les données Integral/IBIS/ISGRI (voir note 4) | M8: lentille
B10: Les valeurs modifiables sont entourées d'un cadre bleu; | K10: satellite 2
B11: Les résultats de calcul sont en rouge sur fond jaune.
A13: note 1 : | B13: W mirroir : | D13: champ de vue du mirroir
B14: W jupe : | D14: champ protégé par la jupe
B15: W collimateur : | D15: 2*p - (W protégé collimateur)
B16: W protégé collimateur : | D16: champ protégé par le collimateur | L16: jupe en tantale
B17: W non protégé : | D17: champ non protégé par la jupe ou le collimateur
D18: (devrait être zéro)
A20: note 2 : | B20: le diamètre d'intégration est le diamètre de la tache où l'on | M20: collimateur en plomb
B21: compte le nombre de photons provenant de la source pour construire
B22: l'image. Le pourcentage de photons par tache est le pourcentage de
B23: photons de la source se trouvant effectivement dans le diamètre d'intégration.
B24: (valeur à étalonner en fonction des propriétés du mirroir)
M26: détecteurs SDD et CdTe
A27: note 3 : | B27: La sensibilité est calculée à S/N sigmas, en tobs secondes, pour
B28: DE/E égal à DE/E.
A31: note 4 : | B31: Le bruit interne peut être recalé sur le bruit ISGRI (voir feuille bruit interne)
B32: Si la pondération est égale à 1, on obtient le bruit d'Armstrong et al. 99. | L32: satellite 1
B33: Si on choisit la pondération proposée, le bruit interne total est
B34: équivalent à celui d'ISGRI (en supposant un spectre ISGRI
B35: identique à celui d'Armstrong).
H42: CONFIGURATION UTILISEE
H43: (échelle non représentative)

Sheet bruit interne
A2: bruit ISGRI : | B2: 350 | C2: cps/s
A3: Emin : | B3: 17 | C3: keV
A4: Emax : | B4: 200 | C4: keV
A5: surface ISGRI : | B5: 2621 | C5: cm²
A7: bruit interne : | B7: =$B$2/($B$4-$B$3)/$B$5 -> 0.00072970939 | C7: cps/s/cm²/keV
A9: Emin CdTe | B9: 17 | C9: keV
A10: Emax CdTe | B10: 200 | C10: keV
A12: bruit interne | B12: =$B$7*($B$10-$B$9) -> 0.13353682 | C12: cps/s/cm²
